
de.schilken.timeout_examples.MainActivityTest:
Error in using pumpAndSettleWithTimeout(de.schilken.timeout_examples.MainActivityTest):
java.lang.Exception: ══╡ EXCEPTION CAUGHT BY FLUTTER TEST FRAMEWORK ╞═════════════════
The following assertion was thrown running a test:
pumpAndSettle timed out

When the exception was thrown, this was the stack:
#0      WidgetTester.pumpAndSettle.<anonymous closure> (package:flutter_test/src/widget_tester.dart:671:11)
<asynchronous suspension>
#1      TestAsyncUtils.guard.<anonymous closure> (package:flutter_test/src/test_async_utils.dart)
<asynchronous suspension>

The test description was:
  using pumpAndSettleWithTimeout
═════════════════════════════════════════════════════════════════

	at dev.flutter.plugins.integration_test.FlutterTestRunner.run(FlutterTestRunner.java:81)
	at org.junit.runners.Suite.runChild(Suite.java:128)
	at org.junit.runners.Suite.runChild(Suite.java:27)
	at org.junit.runners.ParentRunner$3.run(ParentRunner.java:290)
	at org.junit.runners.ParentRunner$1.schedule(ParentRunner.java:71)
	at org.junit.runners.ParentRunner.runChildren(ParentRunner.java:288)
	at org.junit.runners.ParentRunner.access$000(ParentRunner.java:58)
	at org.junit.runners.ParentRunner$2.evaluate(ParentRunner.java:268)
	at org.junit.runners.ParentRunner.run(ParentRunner.java:363)
	at org.junit.runner.JUnitCore.run(JUnitCore.java:137)
	at org.junit.runner.JUnitCore.run(JUnitCore.java:115)
	at androidx.test.internal.runner.TestExecutor.execute(TestExecutor.java:56)
	at androidx.test.runner.AndroidJUnitRunner.onStart(AndroidJUnitRunner.java:392)
	at android.app.Instrumentation$InstrumentationThread.run(Instrumentation.java:2145)

Error in failure caused by timeout(de.schilken.timeout_examples.MainActivityTest):
java.lang.Exception: ══╡ EXCEPTION CAUGHT BY FLUTTER TEST FRAMEWORK ╞═════════════════
The following assertion was thrown running a test:
pumpAndSettle timed out

When the exception was thrown, this was the stack:
#0      WidgetTester.pumpAndSettle.<anonymous closure> (package:flutter_test/src/widget_tester.dart:671:11)
<asynchronous suspension>
#1      TestAsyncUtils.guard.<anonymous closure> (package:flutter_test/src/test_async_utils.dart)
<asynchronous suspension>

The test description was:
  failure caused by timeout
═════════════════════════════════════════════════════════════════

	at dev.flutter.plugins.integration_test.FlutterTestRunner.run(FlutterTestRunner.java:81)
	at org.junit.runners.Suite.runChild(Suite.java:128)
	at org.junit.runners.Suite.runChild(Suite.java:27)
	at org.junit.runners.ParentRunner$3.run(ParentRunner.java:290)
	at org.junit.runners.ParentRunner$1.schedule(ParentRunner.java:71)
	at org.junit.runners.ParentRunner.runChildren(ParentRunner.java:288)
	at org.junit.runners.ParentRunner.access$000(ParentRunner.java:58)
	at org.junit.runners.ParentRunner$2.evaluate(ParentRunner.java:268)
	at org.junit.runners.ParentRunner.run(ParentRunner.java:363)
	at org.junit.runner.JUnitCore.run(JUnitCore.java:137)
	at org.junit.runner.JUnitCore.run(JUnitCore.java:115)
	at androidx.test.internal.runner.TestExecutor.execute(TestExecutor.java:56)
	at androidx.test.runner.AndroidJUnitRunner.onStart(AndroidJUnitRunner.java:392)
	at android.app.Instrumentation$InstrumentationThread.run(Instrumentation.java:2145)
.

Time: 38.317
There were 2 failures:
1) using pumpAndSettleWithTimeout(de.schilken.timeout_examples.MainActivityTest)
java.lang.Exception: ══╡ EXCEPTION CAUGHT BY FLUTTER TEST FRAMEWORK ╞═════════════════
The following assertion was thrown running a test:
pumpAndSettle timed out

When the exception was thrown, this was the stack:
#0      WidgetTester.pumpAndSettle.<anonymous closure> (package:flutter_test/src/widget_tester.dart:671:11)
<asynchronous suspension>
#1      TestAsyncUtils.guard.<anonymous closure> (package:flutter_test/src/test_async_utils.dart)
<asynchronous suspension>

The test description was:
  using pumpAndSettleWithTimeout
═════════════════════════════════════════════════════════════════

	at dev.flutter.plugins.integration_test.FlutterTestRunner.run(FlutterTestRunner.java:81)
	at org.junit.runners.Suite.runChild(Suite.java:128)
	at org.junit.runners.Suite.runChild(Suite.java:27)
	at org.junit.runners.ParentRunner$3.run(ParentRunner.java:290)
	at org.junit.runners.ParentRunner$1.schedule(ParentRunner.java:71)
	at org.junit.runners.ParentRunner.runChildren(ParentRunner.java:288)
	at org.junit.runners.ParentRunner.access$000(ParentRunner.java:58)
	at org.junit.runners.ParentRunner$2.evaluate(ParentRunner.java:268)
	at org.junit.runners.ParentRunner.run(ParentRunner.java:363)
	at org.junit.runner.JUnitCore.run(JUnitCore.java:137)
	at org.junit.runner.JUnitCore.run(JUnitCore.java:115)
	at androidx.test.internal.runner.TestExecutor.execute(TestExecutor.java:56)
	at androidx.test.runner.AndroidJUnitRunner.onStart(AndroidJUnitRunner.java:392)
	at android.app.Instrumentation$InstrumentationThread.run(Instrumentation.java:2145)
2) failure caused by timeout(de.schilken.timeout_examples.MainActivityTest)
java.lang.Exception: ══╡ EXCEPTION CAUGHT BY FLUTTER TEST FRAMEWORK ╞═════════════════
The following assertion was thrown running a test:
pumpAndSettle timed out

When the exception was thrown, this was the stack:
#0      WidgetTester.pumpAndSettle.<anonymous closure> (package:flutter_test/src/widget_tester.dart:671:11)
<asynchronous suspension>
#1      TestAsyncUtils.guard.<anonymous closure> (package:flutter_test/src/test_async_utils.dart)
<asynchronous suspension>

The test description was:
  failure caused by timeout
═════════════════════════════════════════════════════════════════

	at dev.flutter.plugins.integration_test.FlutterTestRunner.run(FlutterTestRunner.java:81)
	at org.junit.runners.Suite.runChild(Suite.java:128)
	at org.junit.runners.Suite.runChild(Suite.java:27)
	at org.junit.runners.ParentRunner$3.run(ParentRunner.java:290)
	at org.junit.runners.ParentRunner$1.schedule(ParentRunner.java:71)
	at org.junit.runners.ParentRunner.runChildren(ParentRunner.java:288)
	at org.junit.runners.ParentRunner.access$000(ParentRunner.java:58)
	at org.junit.runners.ParentRunner$2.evaluate(ParentRunner.java:268)
	at org.junit.runners.ParentRunner.run(ParentRunner.java:363)
	at org.junit.runner.JUnitCore.run(JUnitCore.java:137)
	at org.junit.runner.JUnitCore.run(JUnitCore.java:115)
	at androidx.test.internal.runner.TestExecutor.execute(TestExecutor.java:56)
	at androidx.test.runner.AndroidJUnitRunner.onStart(AndroidJUnitRunner.java:392)
	at android.app.Instrumentation$InstrumentationThread.run(Instrumentation.java:2145)

FAILURES!!!
Tests run: 3,  Failures: 2


